Workbook
Name __EEE07: [1]Alat!$H$20
Name __EEE07: [1]Alat!$H$20
Name __EEE07: [1]Alat!$H$20
Name __EEE07: [1]Alat!$H$20
Name __EEE07: [2]Alat!$H$20
Name A: #REF!
Name A: #REF!
Name A: #REF!
Name A: #REF!
Name A: #REF!
Name amp: '[3]B&U'!$F$12
Name Amplas: #REF!
Name Amplas: #REF!
Name Amplas: #REF!
Name Amplas: #REF!
Name Amplas: #REF!
Name ATAPASBES: #REF!
Name ATAPASBES: #REF!
Name ATAPASBES: #REF!
Name ATAPASBES: #REF!
Name ATAPASBES: #REF!
Name azzzz: #REF!
Name azzzz: #REF!
Name azzzz: #REF!
Name azzzz: #REF!
Name azzzz: #REF!
Name BATUALAMTEMPEL: #REF!
Name BATUALAMTEMPEL: #REF!
Name BATUALAMTEMPEL: #REF!
Name BATUALAMTEMPEL: #REF!
Name BATUALAMTEMPEL: #REF!
Name BATUBELAHPUTIH: #REF!
Name BATUBELAHPUTIH: #REF!
Name BATUBELAHPUTIH: #REF!
Name BATUBELAHPUTIH: #REF!
Name BATUBELAHPUTIH: #REF!
Name BATUKALIBELAH: #REF!
Name BATUKALIBELAH: #REF!
Name BATUKALIBELAH: #REF!
Name BATUKALIBELAH: #REF!
Name BATUKALIBELAH: #REF!
Name BATUMERAH: #REF!
Name BATUMERAH: #REF!
Name BATUMERAH: #REF!
Name BATUMERAH: #REF!
Name BATUMERAH: #REF!
Name begistingd: #REF!
Name begistingd: #REF!
Name begistingd: #REF!
Name begistingd: #REF!
Name begistingd: #REF!
Name begistingt: #REF!
Name begistingt: #REF!
Name begistingt: #REF!
Name begistingt: #REF!
Name begistingt: #REF!
Name BesiBeton: #REF!
Name BesiBeton: #REF!
Name BesiBeton: #REF!
Name BesiBeton: #REF!

Sheet Rekapitulasi
A1: REKAPITULASI
D2: RENCANA ANGGARAN BIAYA (RAB)
A4: PEKERJAAN | C4: : | D4: PEMBANGUNAN GEDUNG A (STRUKTUR DAN ARSITEKTUR)
A5: LOKASI | C5: : | D5: DINAS ABC
A6: KABUPATEN | C6: : | D6: MAJALENGKA
A7: TAHUN ANGGARAN | C7: : | D7: 2019
A9: NO. | B9: URAIAN PEKERJAAN | E9: JUMLAH HARGA (Rp)
A11: 1 | B11: PEKERJAAN PERSIAPAN | E11: =RAB!I14 -> 30503932
A12: 2 | B12: PEKERJAAN TANAH | E12: =RAB!I21 -> 14233630
A13: 3 | B13: PEKERJAAN PONDASI | E13: =RAB!I24 -> 51047321
A14: 4 | B14: PEKERJAAN BETON | E14: =RAB!I46 -> 5.0738291e+08
A15: 5 | B15: PEKERJAAN DINDING, PLESTERAN DAN PASRTISI | E15: =RAB!I51 -> 98716368
A16: 6 | B16: PEKERJAAN PENUTUP LANTAI | E16: =RAB!I55 -> 98810929
A17: 7 | B17: PEKERJAAN ATAP DAN PLAFOND | E17: =RAB!I63 -> 1.5519056e+08
A18: 8 | B18: PEKERJAAN KUSEN, PINTU DAN JENDELA | E18: =RAB!I72 -> 3.7774081e+08
A19: 9 | B19: PEKERJAAN PENGECATAN | E19: =RAB!I77 -> 24103000
A20: JUMLAH | E20: =SUM(E11:E19) -> 1.3577295e+09
A21: PPN 10% | E21: =E20*10% -> 1.3577295e+08
A22: TOTAL JUMLAH | E22: =E20+E21 -> 1.4935024e+09
A23: DIBULATKAN | E23: =TRUNC(E22/1000)*1000 -> 1493502000
A24: TERBILANG | C24: : | D24: # Satu Milyar Empat Ratus Sembilan Puluh Empat Juta Lima Ratus Lima Puluh Dua Ribu Rupiah #

Sheet RAB
A1: RENCANA ANGGARAN BIAYA (RAB)
A3: PEKERJAAN | C3: : | D3: =Rekapitulasi!D4 -> PEMBANGUNAN GEDUNG A (STRUKTUR DAN ARSITEKTUR)
A4: =+Rekapitulasi!A5 -> LOKASI | C4: : | D4: =+Rekapitulasi!D5 -> DINAS ABC
A5: =+Rekapitulasi!A6 -> KABUPATEN | C5: : | D5: =+Rekapitulasi!D6 -> MAJALENGKA
A6: =+Rekapitulasi!A7 -> TAHUN ANGGARAN | C6: : | D6: =+Rekapitulasi!D7 -> 2019
A8: NO | B8: URAIAN PEKERJAAN | E8: VOLUME | F8: SAT. | G8: ANALISA | H8: HARGA SATUAN (Rp) | I8: JUMLAH HARGA (Rp)
A10: I | B10: PEKERJAAN PERSIAPAN
A11: 1 | B11: Pengukuran dan Pemasangan Bouwplank | E11: 126.61 | F11: M' | G11: A.2.2.1.4 | H11: ='Analisa '!K11 -> 101200 | I11: =ROUND(E11*H11,2) -> 12812932
A12: 2 | B12: Pembersihan Lapangan dan Perataan | E12: 180 | F12: M2 | G12: A.2.2.1.9 | H12: ='Analisa '!K25 -> 14950 | I12: =ROUND(E12*H12,2) -> 2691000
A13: =+A12+1 -> 3 | B13: Mobilisasi dan Demobilisasi Alat | E13: 1 | F13: Ls | G13: Taksir | H13: 15000000 | I13: =ROUND(E13*H13,2) -> 15000000
A14: SUB TOTAL I | I14: =SUM(I11:I13) -> 30503932
A15: II | B15: PEKERJAAN TANAH
A16: 1 | B16: Galian Tanah Biasa 1 m | E16: 40 | F16: M3 | G16: A.2.3.1.1 | H16: ='Analisa '!K34 -> 67850 | I16: =ROUND(E16*H16,2) -> 2714000
A17: =+A16+1 -> 2 | B17: Galian Tanah Biasa 2 m | E17: 28 | F17: M3 | G17: A.2.3.1.2 | H17: ='Analisa '!K43 -> 83317.5 | I17: =ROUND(E17*H17,2) -> 2332890
A18: 3 | B18: Urugan Tanah Kembali | E18: 16 | F18: M3 | G18: A.2.3.1.9 | H18: ='Analisa '!K52 -> 16483.333 | I18: =ROUND(E18*H18,2) -> 263733.33
A19: 4 | B19: Urugan Pasir Bawah Pondasi dan Sloof | E19: 8.76 | F19: M3 | G19: A.2.3.1.11 | H19: ='Analisa '!K62 -> 475640 | I19: =ROUND(E19*H19,2) -> 4166606.4
A20: 5 | B20: Urugan Pasir Bawah Lantai | E20: 10 | F20: M3 | G20: A.2.3.1.11 | H20: ='Analisa '!K62 -> 475640 | I20: =ROUND(E20*H20,2) -> 4756400
A21: SUB TOTAL II | I21: =SUM(I16:I20) -> 14233630
A22: III | B22: PEKERJAAN PONDASI
A23: 1 | B23: Pasangan Batu Belah 1Pc : 4Ps | E23: 48.9 | F23: M3 | G23: A.3.2.1.2 | H23: ='Analisa '!K72 -> 1043912.5 | I23: =+H23*E23 -> 51047321
A24: SUB TOTAL III | I24: =SUM(I23:I23) -> 51047321
A25: IV | B25: PEKERJAAN BETON
A26: 1 | B26: Lantai Kerja (Rabat Beton) dibawah Foot Plat T=10 cm | E26: 4.2 | F26: M3 | G26: A.2.3.1.14 | H26: ='Analisa '!K86 -> 901784 | I26: =ROUND(E26*H26,2) -> 3787492.8
A27: 2 | B27: Lantai Kerja (Rabat Beton) Lantai 1 T=10 cm | E27: 18.62 | F27: M3 | G27: A.2.3.1.14 | H27: ='Analisa '!K86 -> 901784 | I27: =ROUND(E27*H27,2) -> 16791218
A28: 3 | B28: Foot Plat (200 x 200) cm K250
B29: a. Cor Manual | E29: 33.6 | F29: M3 | G29: A.4.1.1.8 | H29: ='Analisa '!K102 -> 1115149.2 | I29: =ROUND(E29*$H29,2) -> 37469015
B30: b. Pembesian | E30: 5563.92 | F30: Kg | G30: A.4.1.1.17 | H30: ='Analisa '!K118 -> 14444.575 | I30: =ROUND(E30*$H30,2) -> 80368460
B31: c. Bekisting | E31: 146.8 | F31: M2 | G31: A.4.1.1.20 | H31: ='Analisa '!K131 -> 155399.5 | I31: =ROUND(E31*$H31,2) -> 22812647
A32: 4 | B32: Sloof SL (15 x 30) cm K250
B33: a. Cor Manual | E33: 13.54 | F33: M3 | G33: A.4.1.1.8 | H33: =H29 -> 1115149.2 | I33: =ROUND(E33*H33,2) -> 15099121
B34: b. Pembesian | E34: 1642.79 | F34: Kg | G34: A.4.1.1.17 | H34: ='Analisa '!K118 -> 14444.575 | I34: =ROUND(E34*H34,2) -> 23729403
B35: c. Bekisting | E35: 90.29 | F35: M2 | G35: A.4.1.1.21 | H35: ='Analisa '!K145 -> 165749.5 | I35: =ROUND(E35*H35,2) -> 14965522
A36: 5 | B36: Kolom Struktur (KB1) K250
B37: a. Cor Manual | E37: 16.53 | F37: M3 | G37: A.4.1.1.8 | H37: =+H33 -> 1115149.2 | I37: =ROUND(E37*$H37,2) -> 18433417
B38: b. Pembesian | E38: 5244.35 | F38: Kg | G38: A.4.1.1.17 | H38: =H34 -> 14444.575 | I38: =ROUND(E38*$H38,2) -> 75752407
B39: c. Bekisting | E39: 165.312 | F39: M2 | G39: A.4.1.1.22 | H39: ='Analisa '!K159 -> 399067.25 | I39: =ROUND(E39*$H39,2) -> 65970605
A40: 6 | B40: Balok Struktur Atap (20 x 30) cm K250
B41: a. Cor Manual | E41: 17.913 | F41: M3 | G41: A.4.1.1.8 | H41: =H37 -> 1115149.2 | I41: =ROUND(E41*$H41,2) -> 19975669
B42: b. Pembesian | E42: 2498.18 | F42: Kg | G42: A.4.1.1.17 | H42: =H38 -> 14444.575 | I42: =ROUND(E42*$H42,2) -> 36085148
B43: c. Bekisting | E43: 158.55 | F43: M2 | G43: A.4.1.1.23 | H43: =H39 -> 399067.25 | I43: =ROUND(E43*$H43,2) -> 63272112
...

Sheet Analisa Upah
A1: DAFTAR UPAH PEKERJA
A3: Kode | B3: Uraian | D3: Satuan | E3: Harga Satuan (Rp.) | G3: KET
E4: Harga | F4: Pembulatan | J4: Acuan Berdasarkan UMK yang berlaku di setiap Daerah & PERMENAKER 15/2018 Pasal 19
A5: L.01 | B5: Pekerja/Asisten Tukang/Kenek | D5: Hr | E5: =O12 -> 71540 | F5: 75000 | G5: Pembulatan dari UMK | J5: UMK Kab. Purbalingga (Tahun 2019) | N5: Rp | O5: 1788500 | P5: A
A6: L.02 | B6: Tukang Kayu | D6: Hr | E6: =E5*1.2 -> 85848 | F6: 90000 | G6: 20% > dari Pekerja | J6: Jumlah Hari kerja (6 Hari / Minggu) | L6: Kerja | M6: 08.00 s/d 12.00 | N6: Hari | O6: 25 | P6: B
A7: L.02 | B7: Tukang Batu | D7: Hr | E7: =E6 -> 85848 | F7: =F6 -> 90000 | G7: 20% > dari Pekerja | J7: Jam Kerja (Jam/Hari) | K7: 7 | L7: Istirahat | M7: 12.00 s/d 13.00 | P7: C
A8: L.02 | B8: Tukang Besi | D8: Hr | E8: =E7 -> 85848 | F8: =F7 -> 90000 | G8: 20% > dari Pekerja | L8: Kerja | M8: 13.00 s/d 16.00
A9: L.02 | B9: Tukang Cat | D9: Hr | E9: =E8 -> 85848 | F9: =F8 -> 90000 | G9: 20% > dari Pekerja | J9: Jumlah Hari Kerja (5 Hari / Minggu) | L9: Kerja | M9: 08.00 s/d 12.00 | N9: Hari | O9: 21 | P9: D
A10: L.02 | B10: Tukang Listrik | D10: Hr | E10: =E9 -> 85848 | F10: =F9 -> 90000 | G10: 20% > dari Pekerja | J10: Jam Kerja (Jam/Hari) | K10: 8 | L10: Istirahat | M10: 12.00 s/d 13.00 | P10: E
A11: L.03 | B11: Kepala Tukang | D11: Hr | E11: =E5*1.3 -> 93002 | F11: 95000 | G11: 30% > dari Pekerja | L11: Kerja | M11: 13.00 s/d 17.00
A12: L.04 | B12: Mandor | D12: Hr | E12: =E5*1.5 -> 107310 | F12: 110000 | G12: 50% > dari Pekerja | J12: Upah Per Hari ------ (G) | O12: =O5/O6 -> 71540 | P12: (A/B) atau (A/D)
J13: Upah Per Jam (Dengan Analisa dibagi waktu kerja per hari) ------ (H) | O13: =O12/K7 -> 10220 | P13: (G/C) atau (G/E)
A14: L.01 | B14: Pekerja/Asisten Tukang/Kenek | D14: Jam | E14: =E5/K7 -> 10220 | F14: 10500 | J14: Upah Per Jam (Dengan Analisa dibagi waktu kerja per bulan) ------ (I) | O14: =O5/J21 -> 10338.15 | P14: (A/F)
A15: L.02 | B15: Tukang Kayu | D15: Jam | E15: =E6/K7 -> 12264 | F15: 12500
A16: L.02 | B16: Tukang Batu | D16: Jam | E16: =E15 -> 12264 | F16: 12500 | J16: 12 | K16: Bulan/Tahun
A17: L.02 | B17: Tukang Besi | D17: Jam | E17: =E16 -> 12264 | F17: 12500 | J17: 52 | K17: Minggu/Tahun
A18: L.02 | B18: Tukang Cat | D18: Jam | E18: =E17 -> 12264 | F18: 12500 | J18: 40 | K18: jam/minggu
A19: L.02 | B19: Tukang Listrik | D19: Jam | E19: =E18 -> 12264 | F19: 12500 | J19: =J17/J16 -> 4.3333333 | K19: minggu/bulan
A20: L.03 | B20: Kepala Tukang | D20: Jam | E20: =E11/K7 -> 13286 | F20: 13500 | J20: =J18*J19 -> 173.33333 | K20: jam/bulan
A21: L.04 | B21: Mandor | D21: Jam | E21: =E12/K7 -> 15330 | F21: 15500 | J21: =ROUNDDOWN(J20,0) -> 173 | K21: Pembulatan (Jam/bulan) | N21: F

Sheet Harga Bahan
A1: DAFTAR HARGA SATUAN BAHAN BANGUNAN
A3: No | B3: JENIS BAHAN | C3: SATUAN | D3: HARGA | G3: KETERANGAN
A5: I | B5: BAHAN DASAR
A6: 1 | B6: Batu Kali Belah Ukuran 10/15 | C6: m3 | D6: 300000
A7: 2 | B7: Kerikil / Koral | C7: m3 | D7: 325000
A8: 3 | B8: Batu Bata Merah | C8: Bh | D8: 750
A9: 4 | B9: Pasir | C9: m3 | D9: 325000
A10: 5 | B10: Sirtu | C10: m3 | D10: 280000
A11: 6 | B11: Semen 40 kg/Zak | C11: Zak | D11: 45000 | E11: =D11/40 -> 1125 | F11: kg
A12: II | B12: BAHAN PENUTUP ATAP
A13: 1 | B13: Genteng (Tanah Liat) | C13: bh | D13: 3000
A14: 2 | B14: Nok kerpus (Tanah Liat) | C14: bh | D14: 7800
A15: 3 | B15: Seng Plat
B16: a. BJLS 0,18 lebar 55 cm | C16: m' | D16: 22500
B17: b. BJLS 0,20 lebar 55 cm | C17: m' | D17: 24300
B18: c. BJLS 0,28 lebar 55 cm | C18: m' | D18: 27000
B19: d. BJLS 0,30 lebar 55 cm | C19: m' | D19: 45000
A20: 4 | B20: Seng Gelombang
B21: a. BJLS 0,18 lebar 180 cm | C21: lbr | D21: 36000
B22: b. BJLS 0,20 lebar 180 cm | C22: lbr | D22: 40000
B23: c. BJLS 0,30 lebar 180 cm | C23: lbr | D23: 65000
B24: d. BJLS 0,40 lebar 180 cm | C24: lbr | D24: 58000
A25: III | B25: BAHAN KAYU
A26: 1 | B26: MERANTI
B27: a. Papan 3/20 (Panjang 4 m' / btg) | C27: m3 | D27: 4800000
B28: b. Balok 5/7 (Panjang 4 m' / btg) | C28: m3 | D28: 3000000
B29: c. Balok 6/12 (Panjang 4 m' / btg) | C29: m3 | D29: 3000000
A30: 2 | B30: DOLKEN
B31: a. Sedang 8 x 10 x 400 cm | C31: btg | D31: 22500
B32: b. Kecil 6 x 7 x 400 cm | C32: btg | D32: 20000
B33: c. Besar 10 x 12 x 400 cm | C33: btg | D33: 34000
B34: d. Kayu cetakan | C34: m3 | D34: 1890000
B35: e. Kayu bakar | C35: m3 | D35: 99000
B36: f. Bambu | C36: btg | D36: 15975
A37: IV | B37: BAHAN PENUTUP DINDING / LANTAI
A38: 1 | B38: Keramik
B39: a. 20 X 20 cm | C39: m2 | D39: 55000 | E39: =D39/26 -> 2115.3846 | F39: Buah
B40: b. 20 X 25 cm | C40: m2 | D40: 55000 | E40: =D40/26 -> 2115.3846 | F40: Buah
B41: c. 30 X 30 cm | C41: m2 | D41: 55000 | E41: =D41/8 -> 6875 | F41: Buah
B42: d. 40 X 40 cm | C42: m2 | D42: 55000 | E42: =D42/6 -> 9166.6667 | F42: Buah
...

Sheet Harga Alat
A1: DAFTAR HARGA SATUAN DASAR ALAT
A3: =+Rekapitulasi!A4 -> PEKERJAAN | C3: =[5]Rekap!D4 -> : | D3: =+Rekapitulasi!D4 -> PEMBANGUNAN GEDUNG A (STRUKTUR DAN ARSITEKTUR)
A4: =+Rekapitulasi!A5 -> LOKASI | C4: =[5]Rekap!D5 -> : | D4: =+Rekapitulasi!D5 -> DINAS ABC
A5: =+Rekapitulasi!A6 -> KABUPATEN | C5: =[5]Rekap!D6 -> : | D5: =+Rekapitulasi!D6 -> MAJALENGKA
A6: =+Rekapitulasi!A7 -> TAHUN ANGGARAN | C6: =[5]Rekap!D7 -> : | D6: =+Rekapitulasi!D7 -> 2019
A8: NO | B8: URAIAN | E8: SATUAN | F8: HARGA | G8: KETERANGAN
F9: ( Rp. )
A10: 1 | B10: Asphalt Mixing Plant | E10: Jam | F10: 3250000
A11: =+A10+1 -> 2 | B11: Asphalt Sprayer | E11: Jam | F11: 22500
A12: =+A11+1 -> 3 | B12: Asphalt Finisher | E12: Jam | F12: 225000
A13: =+A12+1 -> 4 | B13: Air Compressor | E13: Jam | F13: 45000
A14: =+A13+1 -> 5 | B14: Wheel Loader | E14: Jam | F14: 185000
A15: =+A14+1 -> 6 | B15: Excavator | E15: Jam | F15: 30000
A16: =+A15+1 -> 7 | B16: Dump Truck, 8-10 m3 | E16: Jam | F16: 100000
A17: =+A16+1 -> 8 | B17: Dump Truck, 3-4 m3 | E17: Jam | F17: 90000
A18: =+A17+1 -> 9 | B18: Motor Grader (Termasuk Operator dan BBM) | E18: Jam | F18: 250000
A19: =+A18+1 -> 10 | B19: Tandem Roller (Termasuk Operator dan BBM) | E19: Jam | F19: 400000
A20: =+A19+1 -> 11 | B20: Pneumatic Tyre Roller | E20: Jam | F20: 200000
A21: =+A20+1 -> 12 | B21: Vibrator Roller | E21: Jam | F21: 195000
A22: =+A21+1 -> 13 | B22: Water Tank Truck | E22: Jam | F22: 300000
... A30: =+A29+1 -> 21 | B30: Concrete Paver | E30: Jam | F30: 300000
A31: 22 | B31: Baby roller | E31: Jam | F31: 550000

Sheet Analisa 
B1: DAFTAR ANALISA PEKERJAAN
B3: =+Rekapitulasi!A4 -> PEKERJAAN | D3: : | E3: =+Rekapitulasi!D4 -> PEMBANGUNAN GEDUNG A (STRUKTUR DAN ARSITEKTUR)
B4: =+Rekapitulasi!A5 -> LOKASI | D4: : | E4: =+Rekapitulasi!D5 -> DINAS ABC
B5: =+Rekapitulasi!A6 -> KABUPATEN | D5: : | E5: =+Rekapitulasi!D6 -> MAJALENGKA
B6: =+Rekapitulasi!A7 -> TAHUN ANGGARAN | D6: : | E6: =+Rekapitulasi!D7 -> 2019
B8: NO. | C8: SNI | D8: KODE | E8: KOEF. | F8: SAT. | G8: URAIAN PEKERJAAN | J8: HARGA | K8: JUMLAH
J9: BAHAN / UPAH | K9: HARGA
J10: ( Rp. ) | K10: ( Rp. )
B11: 1 | C11: A.2.2.1.4 | E11: 1 | F11: M' | G11: Pengukuran dan Pemasangan Bouwplank | K11: =+K24 -> 101200
F12: A | G12: TENAGA | K12: =SUM(K13:K16) -> 18000
D13: L.01 | E13: 0.1 | F13: OH | G13: Pekerja | J13: ='Analisa Upah'!F5 -> 75000 | K13: =+E13*J13 -> 7500
D14: L.02 | E14: 0.1 | F14: OH | G14: Tukang Kayu | J14: ='Analisa Upah'!F6 -> 90000 | K14: =+E14*J14 -> 9000
D15: L.03 | E15: 0.01 | F15: OH | G15: Kepala Tukang | J15: ='Analisa Upah'!F11 -> 95000 | K15: =+E15*J15 -> 950
D16: L.04 | E16: 0.005 | F16: OH | G16: Mandor | J16: ='Analisa Upah'!F12 -> 110000 | K16: =+E16*J16 -> 550
F17: B | G17: BAHAN | K17: =SUM(K18:K20) -> 70000
E18: 0.012 | F18: M3 | G18: Kayu Balok 5/7 | J18: ='Harga Bahan'!D28 -> 3000000 | K18: =+E18*J18 -> 36000
E19: 0.02 | F19: Kg | G19: Paku 2"- 3" | J19: ='Harga Bahan'!D117 -> 20000 | K19: =+E19*J19 -> 400
E20: 0.007 | F20: M3 | G20: Kayu Papan 3/20 | J20: ='Harga Bahan'!D27 -> 4800000 | K20: =+E20*J20 -> 33600
F21: C | G21: PERALATAN | K21: 0
F22: D | G22: Jumlah A + B + C | K22: =+K12+K17+K21 -> 88000
F23: E | G23: Overhead & Profit | I23: 0.15 | K23: =+I23*K22 -> 13200
F24: F | G24: Harga Satuan Pekerjaan ( D + E ) | K24: =+K22+K23 -> 101200
B25: 2 | C25: A.2.2.1.9 | E25: 1 | F25: M2 | G25: Membersihkan Lapangan dan Perataan | K25: =+K33 -> 14950
F26: A | G26: TENAGA | K26: =SUM(K27:K28) -> 13000
D27: L.01 | E27: 0.1 | F27: OH | G27: Pekerja | J27: ='Analisa Upah'!F5 -> 75000 | K27: =+E27*J27 -> 7500
D28: L.04 | E28: 0.05 | F28: OH | G28: Mandor | J28: ='Analisa Upah'!F12 -> 110000 | K28: =+E28*J28 -> 5500
F29: B | G29: BAHAN | K29: 0
F30: C | G30: PERALATAN | K30: 0
F31: D | G31: Jumlah A + B + C | K31: =+K26+K29+K30 -> 13000
F32: E | G32: Overhead & Profit | I32: 0.15 | K32: =+I32*K31 -> 1950
F33: F | G33: Harga Satuan Pekerjaan ( D + E ) | K33: =+K31+K32 -> 14950
B34: 3 | C34: A.2.3.1.1 | E34: 1 | F34: M3 | G34: Menggali Tanah Biasa sedalam 1 M | K34: =+K42 -> 67850
F35: A | G35: TENAGA | K35: =SUM(K36:K37) -> 59000
D36: L.01 | E36: 0.75 | F36: OH | G36: Pekerja | J36: ='Analisa Upah'!F5 -> 75000 | K36: =+E36*J36 -> 56250
D37: L.04 | E37: 0.025 | F37: OH | G37: Mandor | J37: ='Analisa Upah'!F12 -> 110000 | K37: =+E37*J37 -> 2750
F38: B | G38: BAHAN | K38: 0
F39: C | G39: PERALATAN | K39: 0
F40: D | G40: Jumlah A + B + C | K40: =+K35+K38+K39 -> 59000
F41: E | G41: Overhead & Profit | I41: 0.15 | K41: =+I41*K40 -> 8850
F42: F | G42: Harga Satuan Pekerjaan ( D + E ) | K42: =+K40+K41 -> 67850
...

Sheet RAP
A1: RENCANA ANGGARAN PELAKSANAAN (RAP) PROYEK
A3: PEKERJAAN | C3: : | D3: =RAB!D3 -> PEMBANGUNAN GEDUNG A (STRUKTUR DAN ARSITEKTUR)
A4: =+Rekapitulasi!A5 -> LOKASI | C4: : | D4: =+Rekapitulasi!D5 -> DINAS ABC
A5: =+Rekapitulasi!A6 -> KABUPATEN | C5: : | D5: =+Rekapitulasi!D6 -> MAJALENGKA
A6: =+Rekapitulasi!A7 -> TAHUN ANGGARAN | C6: : | D6: =+Rekapitulasi!D7 -> 2019
A8: DURASI WAKTU | C8: : | D8: 90 HARI
A9: PERIODE | C9: : | D9: SEPTEMBER S/D DESEMBER 2019
A11: Catatan :
B12: dihitung baru menggunakan rumus
A13: NO | B13: URAIAN PEKERJAAN | E13: VOL. | F13: SAT. | G13: RENCANA ANGGARAN BIAYA (RAB) | I13: BOBOT NILAI | J13: DURASI | K13: RAP - (UPAH TENAGA HARIAN) | BN13: RAP - (UPAH TENAGA BORONGAN) | BS13: RAP - (UPAH TENAGA + MATERIAL BORONGAN)
K14: TENAGA | S14: MATERIAL / BAHAN | BI14: Alat / Peralatan | BK14: TOTAL RAP | BL14: PROFIT DAN OVERHEAD | BM14: %PROFIT DAN OVERHEAD | BN14: Harga Borongan Jasa (Tenaga) | BO14: Total Harga Borongan Jasa (Tenaga) | BP14: TOTAL RAP | BQ14: PROFIT DAN OVERHEAD | BR14: %PROFIT DAN OVERHEAD | BS14: Harga Borongan (Tenaga + Material) | BT14: Total Harga Borongan (Tenaga + Material) | BU14: TOTAL RAP | BV14: PROFIT DAN OVERHEAD | BW14: %PROFIT DAN OVERHEAD
G15: HARGA SATUAN | H15: JUMLAH HARGA | K15: Pekerja | L15: Tukang Kayu | M15: Tukang Batu | N15: Tukang Besi | O15: Tukang Cat | P15: Tukang Listrik | Q15: Kepala Tukang | R15: Mandor | S15: Kaso 5/7 | T15: Balok 6/12 | U15: Dolken D 8 cm | V15: Papan 3/20 | W15: Multiplek 9 mm | X15: Gypsum 9 mm | Y15: Bata Merah | Z15: Pasir | AA15: Kerikil | AB15: Batu Belah 15/20 | AC15: Semen | AD15: Air | AE15: Besi | AF15: Hollow 40x40 | AG15: Hollow 20x40 | AH15: Baja Gording | AI15: Baja WF | AJ15: Kusen Alumunium | AK15: Profil Almunium Jendela / Pintu | AL15: Profil Alumunium Kaca | AM15: Alumunium Strip | AN15: Kaca Bening 5 mm | AO15: Kaca Es 5 mm | AP15: Sealant | AQ15: Kawat Bendrat | AR15: Cat Meni Besi | AS15: Atap Seng Gelombang | AT15: Seng Plat | AU15: Minyak Bekisting | AV15: Paku Sekrup Baja | AW15: Paku Sekrup Gypsum | AX15: Sekrup Alumunium | AY15: Paku 1''-5" | AZ15: Plamir | BA15: Sealer Interior | BB15: Sealer Eksterior | BC15: Cat Interior Dinding | BD15: Cat Interior Plafond | BE15: Cat Eksterior Dinding | BF15: Semen Nat | BG15: Keramik 20x20 | BH15: Granite 60 x 60 | BI15: Mobilisasi dan Demobilisasi | BJ15: Sewa Molen Cor
G16: Rp | H16: Rp | I16: % | J16: Hari | K16: OH | L16: OH | M16: OH | N16: OH | O16: OH | P16: OH | Q16: OH | R16: OH | S16: M3 | T16: M3 | U16: btg | V16: M3 | W16: Lembar | X16: Lembar | Y16: Buah | Z16: M3 | AA16: M3 | AB16: M3 | AC16: Zak | AD16: Ltr | AE16: Kg | AF16: btg | AG16: btg | AH16: Kg | AI16: Kg | AJ16: btg | AK16: btg | AL16: btg | AM16: btg | AN16: m2 | AO16: m2 | AP16: Tube | AQ16: kg | AR16: Kg | AS16: Lbr | AT16: Lbr | AU16: ltr | AV16: Kg | AW16: Kg | AX16: bh | AY16: Kg | AZ16: Kg | BA16: 25 kg/Pail | BB16: 25 kg/Pail | BC16: 25 kg/Pail | BD16: 25 kg/Pail | BE16: 25 kg/Pail | BF16: 1 Kg / Bks | BG16: Dus | BH16: Dus | BI16: Ls | BJ16: Hari | BK16: Rp | BL16: Rp | BM16: % | BN16: Rp | BO16: Rp | BP16: Rp | BQ16: Rp | BR16: % | BS16: Rp | BT16: Rp | BU16: Rp | BV16: Rp | BW16: %
A17: A | B17: B | E17: C | F17: D | G17: E | H17: F = C x E | I17: G = F / Total Seluruh x 100 | J17: H | K17: J | L17: K | M17: L | N17: M | O17: N | P17: O | Q17: P | R17: Q | S17: R | T17: S | U17: T | V17: U | W17: V | X17: W | Y17: X | Z17: Y | AA17: Z | AB17: AA | AC17: AB | AD17: AC | AE17: AD | AF17: AE | AG17: AF | AH17: AG | AI17: AH | AJ17: AI | AK17: AJ | AL17: AK | AM17: AL | AN17: AM | AO17: AN | AP17: AO | AQ17: AP | AR17: AQ | AS17: AR | AT17: AS | AU17: AT | AV17: AU | AW17: AV | AX17: AW | AY17: AX | AZ17: AY | BA17: AZ | BB17: BA | BC17: BB | BD17: BC | BE17: BD | BF17: BE | BG17: BF | BH17: BG | BI17: BH | BJ17: BI | BK17: BJ | BL17: BK | BM17: BL | BN17: BM | BO17: BN = BM x C | BP17: BO | BQ17: BP | BR17: BQ | BS17: BR | BT17: BS = BR x C | BU17: BT | BV17: BU | BW17: BV
A18: I | B18: PEKERJAAN PERSIAPAN
A19: 1 | B19: Pengukuran dan Pemasangan Bouwplank | E19: 126.61 | F19: M' | G19: ='Analisa '!K11 -> 101200 | H19: =ROUND(E19*G19,2) -> 12812932 | I19: =H19/$H$86*100 -> 0.94370288 | J19: ='Analisa RAP I'!K15 -> 2 | K19: ='Analisa RAP I'!O16 -> 6 | L19: ='Analisa RAP I'!O17 -> 6 | M19: 0 | N19: 0 | O19: 0 | P19: 0 | Q19: ='Analisa RAP I'!O18 -> 0 | R19: ='Analisa RAP I'!O19 -> 1 | S19: ='Analisa RAP I'!O21 -> 1.5 | T19: 0 | U19: 0 | V19: ='Analisa RAP I'!O23 -> 1 | AY19: ='Analisa RAP I'!O22 -> 2.5 | BI19: 0 | BK19: ='Analisa RAP I'!U15 -> 11470000 | BL19: ='Analisa RAP I'!W15 -> 1342932 | BM19: ='Analisa RAP I'!X15 -> 10.481067 | BN19: ='Analisa RAP I'!Z15 -> 16000 | BO19: =E19*BN19 -> 2025760 | BP19: ='Analisa RAP I'!AC15 -> 11375760 | BQ19: ='Analisa RAP I'!AD15 -> 1437172 | BR19: ='Analisa RAP I'!AE15 -> 11.216574 | BS19: ='Analisa RAP I'!AG15 -> 90000 | BT19: =E19*BS19 -> 11394900 | BU19: ='Analisa RAP I'!AJ15 -> 11394900 | BV19: ='Analisa RAP I'!AK15 -> 1418032 | BW19: ='Analisa RAP I'!AL15 -> 11.067194
A20: 2 | B20: Pembersihan Lapangan dan Perataan | E20: 180 | F20: M2 | G20: ='Analisa '!K25 -> 14950 | H20: =ROUND(E20*G20,2) -> 2691000 | I20: =H20/$H$86*100 -> 0.19819854 | J20: ='Analisa RAP I'!K35 -> 3 | K20: ='Analisa RAP I'!O36 -> 6 | L20: 0 | M20: 0 | N20: 0 | O20: 0 | P20: 0 | Q20: 0 | R20: ='Analisa RAP I'!O37 -> 1 | S20: 0 | T20: 0 | U20: 0 | V20: 0 | AY20: 0 | BI20: 0 | BK20: ='Analisa RAP I'!U35 -> 1650000 | BL20: ='Analisa RAP I'!W35 -> 1041000 | BM20: ='Analisa RAP I'!X35 -> 38.684504 | BN20: ='Analisa RAP I'!Z35 -> 9000 | BO20: =E20*BN20 -> 1620000 | BP20: ='Analisa RAP I'!AC35 -> 1620000 | BQ20: ='Analisa RAP I'!AD35 -> 1071000 | BR20: ='Analisa RAP I'!AE35 -> 39.799331 | BS20: ='Analisa RAP I'!AG35 -> 9000 | BT20: =E20*BS20 -> 1620000 | BU20: ='Analisa RAP I'!AJ35 -> 1620000 | BV20: ='Analisa RAP I'!AK35 -> 1071000 | BW20: ='Analisa RAP I'!AL35 -> 39.799331
A21: 3 | B21: Mobilisasi dan Demobilisasi Alat | E21: 1 | F21: Ls | G21: 15000000 | H21: =ROUND(E21*G21,2) -> 15000000 | I21: =H21/$H$86*100 -> 1.1047856 | J21: ='Analisa RAP I'!K54 -> 4 | K21: 0 | L21: 0 | M21: 0 | N21: 0 | O21: 0 | P21: 0 | Q21: 0 | R21: 0 | S21: 0 | T21: 0 | U21: 0 | V21: 0 | AY21: 0 | BI21: 1 | BK21: ='Analisa RAP I'!U54 -> 15000000 | BL21: ='Analisa RAP I'!W54 -> 0 | BM21: ='Analisa RAP I'!X54 -> 0 | BN21: ='Analisa RAP I'!Z54 -> 15000000 | BO21: =E21*BN21 -> 15000000 | BP21: ='Analisa RAP I'!AC54 -> 15000000 | BQ21: ='Analisa RAP I'!AD54 -> 0 | BR21: ='Analisa RAP I'!AE54 -> 0 | BS21: ='Analisa RAP I'!AG54 -> 15000000 | BT21: =E21*BS21 -> 15000000 | BU21: ='Analisa RAP I'!AJ54 -> 15000000 | BV21: ='Analisa RAP I'!AK54 -> 0 | BW21: ='Analisa RAP I'!AL54 -> 0
A22: SUB TOTAL I | H22: =SUM(H19:H21) -> 30503932 | I22: =SUM(I19:I21) -> 2.2466871 | J22: - | K22: =SUM(K19:K21) -> 12 | L22: =SUM(L19:L21) -> 6 | M22: =SUM(M19:M21) -> 0 | N22: =SUM(N19:N21) -> 0 | O22: =SUM(O19:O21) -> 0 | P22: =SUM(P19:P21) -> 0 | Q22: =SUM(Q19:Q21) -> 0 | R22: =SUM(R19:R21) -> 2 | ... BL22: =SUM(BL19:BL21) -> 2383932 | BM22: =BL22/H22*100 -> 7.815163 | BN22: 0 | BO22: =SUM(BO19:BO21) -> 18645760 | BP22: =SUM(BP19:BP21) -> 27995760 | BQ22: =SUM(BQ19:BQ21) -> 2508172 | BR22: =BQ22/H22*100 -> 8.2224547 | BS22: 0 | BT22: =SUM(BT19:BT21) -> 28014900 | BU22: =SUM(BU19:BU21) -> 28014900 | BV22: =SUM(BV19:BV21) -> 2489032 | BW22: =BV22/H22*100 -> 8.1597087
A23: II | B23: PEKERJAAN TANAH
A24: 1 | B24: Galian Tanah Biasa 1 m | E24: 40 | F24: M3 | G24: ='Analisa '!K34 -> 67850 | H24: =ROUND(E24*G24,2) -> 2714000 | I24: =H24/$H$86*100 -> 0.19989255 | J24: ='Analisa RAP II'!K15 -> 3 | K24: ='Analisa RAP II'!O16 -> 10 | L24: 0 | M24: 0 | N24: 0 | O24: 0 | P24: 0 | Q24: 0 | R24: ='Analisa RAP II'!O17 -> 1 | S24: 0 | V24: 0 | AY24: 0 | BI24: 0 | BK24: ='Analisa RAP II'!U15 -> 2550000 | BL24: ='Analisa RAP II'!W15 -> 164000 | BM24: ='Analisa RAP II'!X15 -> 6.0427413 | BN24: ='Analisa RAP II'!Z15 -> 60000 | BO24: =E24*BN24 -> 2400000 | BP24: ='Analisa RAP II'!AC15 -> 2400000 | BQ24: ='Analisa RAP II'!AD15 -> 314000 | BR24: ='Analisa RAP II'!AE15 -> 11.569639 | BS24: ='Analisa RAP II'!AG15 -> 60000 | BT24: =E24*BS24 -> 2400000 | BU24: ='Analisa RAP II'!AJ15 -> 2400000 | BV24: ='Analisa RAP II'!AK15 -> 314000 | BW24: ='Analisa RAP II'!AL15 -> 11.569639
A25: =+A24+1 -> 2 | B25: Galian Tanah Biasa 2 m | E25: 28 | F25: M3 | G25: ='Analisa '!K43 -> 83317.5 | H25: =ROUND(E25*G25,2) -> 2332890 | I25: =H25/$H$86*100 -> 0.17182289 | J25: ='Analisa RAP II'!K34 -> 4 | K25: ='Analisa RAP II'!O35 -> 6 | L25: 0 | M25: 0 | N25: 0 | O25: 0 | P25: 0 | Q25: 0 | R25: ='Analisa RAP II'!O36 -> 1 | S25: 0 | V25: 0 | AY25: 0 | BI25: 0 | BK25: ='Analisa RAP II'!U34 -> 2200000 | BL25: ='Analisa RAP II'!W34 -> 132890 | BM25: ='Analisa RAP II'!X34 -> 5.696368 | BN25: ='Analisa RAP II'!Z34 -> 60000 | BO25: =E25*BN25 -> 1680000 | BP25: ='Analisa RAP II'!AC34 -> 1680000 | BQ25: ='Analisa RAP II'!AD34 -> 652890 | BR25: ='Analisa RAP II'!AE34 -> 27.986317 | BS25: ='Analisa RAP II'!AG34 -> 60000 | BT25: =E25*BS25 -> 1680000 | BU25: ='Analisa RAP II'!AJ34 -> 1680000 | BV25: ='Analisa RAP II'!AK34 -> 652890 | BW25: ='Analisa RAP II'!AL34 -> 27.986317
A26: 3 | B26: Urugan Tanah Kembali | E26: 16 | F26: M3 | G26: ='Analisa '!K52 -> 16483.333 | H26: =ROUND(E26*G26,2) -> 263733.33 | I26: =H26/$H$86*100 -> 0.019424586 | J26: ='Analisa RAP II'!K54 -> 1 | K26: ='Analisa RAP II'!O55 -> 2 | L26: 0 | M26: 0 | N26: 0 | O26: 0 | P26: 0 | Q26: 0 | R26: ='Analisa RAP II'!O56 -> 1 | S26: 0 | V26: 0 | AY26: 0 | BI26: 0 | BK26: ='Analisa RAP II'!U54 -> 250000 | BL26: ='Analisa RAP II'!W54 -> 13733.33 | BM26: ='Analisa RAP II'!X54 -> 5.2072789 | BN26: ='Analisa RAP II'!Z54 -> 15000 | BO26: =E26*BN26 -> 240000 | BP26: ='Analisa RAP II'!AC54 -> 240000 | BQ26: ='Analisa RAP II'!AD54 -> 23733.33 | BR26: ='Analisa RAP II'!AE54 -> 8.9989877 | BS26: ='Analisa RAP II'!AG54 -> 15000 | BT26: =E26*BS26 -> 240000 | BU26: ='Analisa RAP II'!AJ54 -> 240000 | BV26: ='Analisa RAP II'!AK54 -> 23733.33 | BW26: ='Analisa RAP II'!AL54 -> 8.9989877
A27: 4 | B27: Urugan Pasir Bawah Pondasi dan Sloof | E27: 8.76 | F27: M3 | G27: ='Analisa '!K62 -> 475640 | H27: =ROUND(E27*G27,2) -> 4166606.4 | I27: =H27/$H$86*100 -> 0.30688046 | J27: ='Analisa RAP II'!K73 -> 1 | K27: ='Analisa RAP II'!O74 -> 3 | L27: 0 | M27: 0 | N27: 0 | O27: 0 | P27: 0 | Q27: 0 | R27: ='Analisa RAP II'!O75 -> 1 | S27: 0 | V27: 0 | Z27: ='Analisa RAP II'!O77 -> 10.5 | AA27: 0 | AB27: 0 | AC27: 0 | AY27: 0 | BI27: 0 | BJ27: 0 | BK27: ='Analisa RAP II'!U73 -> 3737500 | BL27: ='Analisa RAP II'!W73 -> 429106.4 | BM27: ='Analisa RAP II'!X73 -> 10.298703 | BN27: ='Analisa RAP II'!Z73 -> 32500 | BO27: =E27*BN27 -> 284700 | BP27: ='Analisa RAP II'!AC73 -> 3697200 | BQ27: ='Analisa RAP II'!AD73 -> 469406.4 | BR27: ='Analisa RAP II'!AE73 -> 11.265917 | BS27: ='Analisa RAP II'!AG73 -> 420000 | BT27: =E27*BS27 -> 3679200 | BU27: ='Analisa RAP II'!AJ73 -> 3679200 | BV27: ='Analisa RAP II'!AK73 -> 487406.4 | BW27: ='Analisa RAP II'!AL73 -> 11.697923
A28: 5 | B28: Urugan Pasir Bawah Lantai | E28: 10 | F28: M3 | G28: ='Analisa '!K62 -> 475640 | H28: =ROUND(E28*G28,2) -> 4756400 | I28: =H28/$H$86*100 -> 0.35032016 | J28: ='Analisa RAP II'!K92 -> 1 | K28: ='Analisa RAP II'!O93 -> 3 | L28: 0 | M28: 0 | N28: 0 | O28: 0 | P28: 0 | Q28: 0 | R28: ='Analisa RAP II'!O94 -> 1 | S28: 0 | V28: 0 | Z28: ='Analisa RAP II'!O96 -> 12 | AA28: 0 | AB28: 0 | AC28: 0 | AY28: 0 | BI28: 0 | BJ28: 0 | BK28: ='Analisa RAP II'!U92 -> 4225000 | BL28: ='Analisa RAP II'!W92 -> 531400 | BM28: ='Analisa RAP II'!X92 -> 11.172315 | BN28: ='Analisa RAP II'!Z92 -> 32500 | BO28: =E28*BN28 -> 325000 | BP28: ='Analisa RAP II'!AC92 -> 4225000 | BQ28: ='Analisa RAP II'!AD92 -> 531400 | BR28: ='Analisa RAP II'!AE92 -> 11.172315 | BS28: ='Analisa RAP II'!AG92 -> 420000 | BT28: =E28*BS28 -> 4200000 | BU28: ='Analisa RAP II'!AJ92 -> 4200000 | BV28: ='Analisa RAP II'!AK92 -> 556400 | BW28: ='Analisa RAP II'!AL92 -> 11.697923
A29: SUB TOTAL II | H29: =SUM(H24:H28) -> 14233630 | I29: =SUM(I24:I28) -> 1.0483406 | J29: 0 | K29: =SUM(K24:K28) -> 24 | L29: =SUM(L24:L28) -> 0 | M29: =SUM(M24:M28) -> 0 | N29: =SUM(N24:N28) -> 0 | O29: =SUM(O24:O28) -> 0 | P29: =SUM(P24:P28) -> 0 | Q29: =SUM(Q24:Q28) -> 0 | R29: =SUM(R24:R28) -> 5 | ... BL29: =SUM(BL24:BL28) -> 1271129.7 | BM29: =BL29/H29*100 -> 8.9304679 | BN29: 0 | BO29: =SUM(BO24:BO28) -> 4929700 | BP29: =SUM(BP24:BP28) -> 12242200 | BQ29: =SUM(BQ24:BQ28) -> 1991429.7 | BR29: =BQ29/H29*100 -> 13.991018 | BS29: 0 | BT29: =SUM(BT24:BT28) -> 12199200 | BU29: =SUM(BU24:BU28) -> 12199200 | BV29: =SUM(BV24:BV28) -> 2034429.7 | BW29: =BV29/H29*100 -> 14.29312
A30: III | B30: PEKERJAAN PONDASI
A31: 1 | B31: Pasangan Batu Belah 1Pc : 4Ps | E31: 48.9 | F31: M3 | G31: ='Analisa '!K72 -> 1043912.5 | H31: =+G31*E31 -> 51047321 | I31: =H31/$H$86*100 -> 3.7597565 | J31: ='Analisa RAP III'!K16 -> 4 | K31: ='Analisa RAP III'!O17 -> 18 | L31: 0 | M31: ='Analisa RAP III'!O18 -> 9 | N31: 0 | O31: 0 | P31: 0 | Q31: 0 | R31: ='Analisa RAP III'!O20 -> 1 | S31: 0 | V31: 0 | Z31: ='Analisa RAP III'!O24 -> 25.5 | AA31: 0 | AB31: ='Analisa RAP III'!O22 -> 59 | AC31: ='Analisa RAP III'!O23 -> 200 | AY31: 0 | BI31: 0 | BJ31: 0 | BK31: ='Analisa RAP III'!U16 -> 43847500 | BL31: ='Analisa RAP III'!W16 -> 7199821.2 | BM31: ='Analisa RAP III'!X16 -> 14.10421 | BN31: ='Analisa RAP III'!Z16 -> 180000 | BO31: =E31*BN31 -> 8802000 | BP31: ='Analisa RAP III'!AC16 -> 43789500 | BQ31: ='Analisa RAP III'!AD16 -> 7257821.2 | BR31: ='Analisa RAP III'!AE16 -> 14.21783 | BS31: ='Analisa RAP III'!AG16 -> 875000 | BT31: =E31*BS31 -> 42787500 | BU31: ='Analisa RAP III'!AJ16 -> 42787500 | BV31: ='Analisa RAP III'!AK16 -> 8259821.2 | BW31: ='Analisa RAP III'!AL16 -> 16.180714
A32: SUB TOTAL III | H32: =SUM(H31:H31) -> 51047321 | I32: =SUM(I31:I31) -> 3.7597565 | J32: 0 | K32: =SUM(K31:K31) -> 18 | L32: =SUM(L31:L31) -> 0 | M32: =SUM(M31:M31) -> 9 | N32: =SUM(N31:N31) -> 0 | O32: =SUM(O31:O31) -> 0 | P32: =SUM(P31:P31) -> 0 | Q32: =SUM(Q31:Q31) -> 0 | R32: =SUM(R31:R31) -> 1 | ... BL32: =SUM(BL31:BL31) -> 7199821.2 | BM32: =BL32/H32*100 -> 14.10421 | BN32: 0 | BO32: =SUM(BO31) -> 8802000 | BP32: =SUM(BP31:BP31) -> 43789500 | BQ32: =SUM(BQ31:BQ31) -> 7257821.2 | BR32: =BQ32/H32*100 -> 14.21783 | BS32: 0 | BT32: =SUM(BT31) -> 42787500 | BU32: =SUM(BU31:BU31) -> 42787500 | BV32: =SUM(BV31:BV31) -> 8259821.2 | BW32: =BV32/H32*100 -> 16.180714
A33: IV | B33: PEKERJAAN BETON
A34: 1 | B34: Lantai Kerja (Rabat Beton) dibawah Foot Plat T=10 cm | E34: 4.2 | F34: M3 | G34: ='Analisa '!K86 -> 901784 | H34: =ROUND(E34*G34,2) -> 3787492.8 | I34: =H34/$H$86*100 -> 0.27895784 | J34: ='Analisa RAP IV'!K18 -> 1 | K34: ='Analisa RAP IV'!O19 -> 5 | L34: 0 | M34: ='Analisa RAP IV'!O20 -> 1 | N34: 0 | O34: 0 | P34: 0 | Q34: 0 | R34: ='Analisa RAP IV'!O22 -> 1 | S34: 0 | V34: 0 | Z34: ='Analisa RAP IV'!O25 -> 2.5 | AA34: ='Analisa RAP IV'!O26 -> 3 | AB34: 0 | AC34: ='Analisa RAP IV'!O24 -> 24 | AD34: ='Analisa RAP IV'!O27 -> 840 | AY34: 0 | BI34: 0 | BJ34: ='Analisa RAP IV'!O29 -> 1 | BK34: ='Analisa RAP IV'!U18 -> 3591780 | BL34: ='Analisa RAP IV'!W18 -> 195712.8 | BM34: ='Analisa RAP IV'!X18 -> 5.1673445 | BN34: ='Analisa RAP IV'!Z18 -> 125000 | BO34: =E34*BN34 -> 525000 | BP34: ='Analisa RAP IV'!AC18 -> 3556780 | BQ34: ='Analisa RAP IV'!AD18 -> 230712.8 | BR34: ='Analisa RAP IV'!AE18 -> 6.0914386 | BS34: ='Analisa RAP IV'!AG18 -> 800000 | BT34: =E34*BS34 -> 3360000 | BU34: ='Analisa RAP IV'!AJ18 -> 3510000 | BV34: ='Analisa RAP IV'!AK18 -> 277492.8 | BW34: ='Analisa RAP IV'!AL18 -> 7.3265565
A35: 2 | B35: Lantai Kerja (Rabat Beton) Lantai 1 T=10 cm | E35: 18.62 | F35: M3 | G35: ='Analisa '!K86 -> 901784 | H35: =ROUND(E35*G35,2) -> 16791218 | I35: =H35/$H$86*100 -> 1.2367131 | J35: ='Analisa RAP IV'!K41 -> 2 | K35: ='Analisa RAP IV'!O42 -> 10 | L35: 0 | M35: ='Analisa RAP IV'!O43 -> 2 | N35: 0 | O35: 0 | P35: 0 | Q35: 0 | R35: ='Analisa RAP IV'!O45 -> 1 | S35: 0 | V35: 0 | Z35: ='Analisa RAP IV'!O48 -> 10.5 | AA35: ='Analisa RAP IV'!O49 -> 13 | AB35: 0 | AC35: ='Analisa RAP IV'!O47 -> 107 | AD35: ='Analisa RAP IV'!O50 -> 3724 | AY35: 0 | BI35: 0 | BJ35: ='Analisa RAP IV'!O52 -> 2 | BK35: ='Analisa RAP IV'!U41 -> 14855808 | BL35: ='Analisa RAP IV'!W41 -> 1935410.1 | BM35: ='Analisa RAP IV'!X41 -> 11.526323 | BN35: ='Analisa RAP IV'!Z41 -> 100000 | BO35: =E35*BN35 -> 1862000 | BP35: ='Analisa RAP IV'!AC41 -> 14677808 | BQ35: ='Analisa RAP IV'!AD41 -> 2113410.1 | BR35: ='Analisa RAP IV'!AE41 -> 12.586401 | BS35: ='Analisa RAP IV'!AG41 -> 750000 | BT35: =E35*BS35 -> 13965000 | BU35: ='Analisa RAP IV'!AJ41 -> 14265000 | BV35: ='Analisa RAP IV'!AK41 -> 2526218.1 | BW35: ='Analisa RAP IV'!AL41 -> 15.044877
A36: 3 | B36: Foot Plat Foot Plat (200 x 200) cm K250
B37: a. Cor Manual | E37: 33.6 | F37: M3 | G37: ='Analisa '!K102 -> 1115149.2 | H37: =ROUND(E37*$G37,2) -> 37469015 | I37: =H37/$H$86*100 -> 2.759682 | J37: ='Analisa RAP IV'!K64 -> 3 | K37: ='Analisa RAP IV'!O65 -> 18 | L37: 0 | M37: ='Analisa RAP IV'!O66 -> 3 | N37: 0 | O37: 0 | P37: 0 | Q37: 0 | R37: ='Analisa RAP IV'!O68 -> 1 | S37: 0 | V37: 0 | Z37: ='Analisa RAP IV'!O71 -> 14.5 | AA37: ='Analisa RAP IV'!O72 -> 24.5 | AB37: 0 | AC37: ='Analisa RAP IV'!O70 -> 323 | AD37: ='Analisa RAP IV'!O73 -> 7224 | AY37: 0 | BI37: 0 | BJ37: ='Analisa RAP IV'!O52 -> 2 | BK37: ='Analisa RAP IV'!U64 -> 32897808 | BL37: ='Analisa RAP IV'!W64 -> 4571206.8 | BM37: ='Analisa RAP IV'!X64 -> 12.199965 | BN37: ='Analisa RAP IV'!Z64 -> 150000 | BO37: =E37*BN37 -> 5040000 | BP37: ='Analisa RAP IV'!AC64 -> 32822808 | BQ37: ='Analisa RAP IV'!AD64 -> 4646206.8 | BR37: ='Analisa RAP IV'!AE64 -> 12.400131 | BS37: ='Analisa RAP IV'!AG64 -> 950000 | BT37: =E37*BS37 -> 31920000 | BU37: ='Analisa RAP IV'!AJ64 -> 32370000 | BV37: ='Analisa RAP IV'!AK64 -> 5099014.8 | BW37: ='Analisa RAP IV'!AL64 -> 13.608617
B38: b. Pembesian' | E38: 5563.92 | F38: Kg | G38: ='Analisa '!K118 -> 14444.575 | H38: =ROUND(E38*$G38,2) -> 80368460 | I38: =H38/$H$86*100 -> 5.919328 | J38: ='Analisa RAP IV'!K155 -> 4 | K38: ='Analisa RAP IV'!O156 -> 10 | N38: ='Analisa RAP IV'!O157 -> 10 | R38: ='Analisa RAP IV'!O159 -> 1 | AE38: ='Analisa RAP IV'!O161 -> 5843 | AQ38: ='Analisa RAP IV'!O162 -> 83.5 | BK38: ='Analisa RAP IV'!U155 -> 69612750 | BL38: ='Analisa RAP IV'!W155 -> 10755710 | BM38: ='Analisa RAP IV'!X155 -> 13.382998 | BN38: ='Analisa RAP IV'!Z155 -> 1200 | BO38: =E38*BN38 -> 6676704 | BP38: ='Analisa RAP IV'!AC155 -> 69489454 | BQ38: ='Analisa RAP IV'!AD155 -> 10879006 | BR38: ='Analisa RAP IV'!AE155 -> 13.536412 | BS38: ='Analisa RAP IV'!AG155 -> 12000 | BT38: =E38*BS38 -> 66767040 | BU38: ='Analisa RAP IV'!AJ155 -> 66767040 | BV38: ='Analisa RAP IV'!AK155 -> 13601420 | BW38: ='Analisa RAP IV'!AL155 -> 16.923828
B39: c. Bekisting | E39: 146.8 | F39: M2 | G39: ='Analisa '!K131 -> 155399.5 | H39: =ROUND(E39*$G39,2) -> 22812647 | I39: =H39/$H$86*100 -> 1.6802056 | J39: ='Analisa RAP IV'!K243 -> 4 | K39: ='Analisa RAP IV'!O244 -> 20 | L39: ='Analisa RAP IV'!O245 -> 10 | R39: ='Analisa RAP IV'!O247 -> 1 | S39: ='Analisa RAP IV'!O249 -> 3 | AU39: ='Analisa RAP IV'!O251 -> 15 | AY39: ='Analisa RAP IV'!O250 -> 44 | BK39: ='Analisa RAP IV'!U243 -> 19890000 | BL39: ='Analisa RAP IV'!W243 -> 2922646.6 | BM39: ='Analisa RAP IV'!X243 -> 12.811519 | BN39: ='Analisa RAP IV'!Z243 -> 60000 | BO39: =E39*BN39 -> 8808000 | BP39: ='Analisa RAP IV'!AC243 -> 18898000 | BQ39: ='Analisa RAP IV'!AD243 -> 3914646.6 | BR39: ='Analisa RAP IV'!AE243 -> 17.159984 | BS39: ='Analisa RAP IV'!AG243 -> 130000 | BT39: =E39*BS39 -> 19084000 | BU39: ='Analisa RAP IV'!AJ243 -> 19084000 | BV39: ='Analisa RAP IV'!AK243 -> 3728646.6 | BW39: ='Analisa RAP IV'!AL243 -> 16.344647
A40: 4 | B40: Sloof SL (15 x 30) cm K250
B41: a. Cor Manual | E41: 13.54 | F41: M3 | G41: =G37 -> 1115149.2 | H41: =ROUND(E41*G41,2) -> 15099121 | I41: =H41/$H$86*100 -> 1.1120861 | J41: ='Analisa RAP IV'!K87 -> 2 | K41: ='Analisa RAP IV'!O88 -> 11 | M41: ='Analisa RAP IV'!O89 -> 2 | R41: ='Analisa RAP IV'!O91 -> 1 | Z41: ='Analisa RAP IV'!O94 -> 6 | AA41: ='Analisa RAP IV'!O95 -> 10 | AC41: ='Analisa RAP IV'!O93 -> 130 | AD41: ='Analisa RAP IV'!O96 -> 2912 | BJ41: ='Analisa RAP IV'!O98 -> 2 | BK41: ='Analisa RAP IV'!U87 -> 13589504 | BL41: ='Analisa RAP IV'!W87 -> 1509616.8 | BM41: ='Analisa RAP IV'!X87 -> 9.9980447 | BN41: ='Analisa RAP IV'!Z87 -> 150000 | BO41: =E41*BN41 -> 2031000 | BP41: ='Analisa RAP IV'!AC87 -> 13430504 | BQ41: ='Analisa RAP IV'!AD87 -> 1668616.8 | BR41: ='Analisa RAP IV'!AE87 -> 11.051086 | BS41: ='Analisa RAP IV'!AG87 -> 950000 | BT41: =E41*BS41 -> 12863000 | BU41: ='Analisa RAP IV'!AJ87 -> 13163000 | BV41: ='Analisa RAP IV'!AK87 -> 1936120.8 | BW41: ='Analisa RAP IV'!AL87 -> 12.822739
B42: b. Pembesian' | E42: 1642.79 | F42: Kg | G42: ='Analisa '!K118 -> 14444.575 | H42: =ROUND(E42*G42,2) -> 23729403 | I42: =H42/$H$86*100 -> 1.7477269 | J42: ='Analisa RAP IV'!K177 -> 2 | K42: ='Analisa RAP IV'!O178 -> 6 | N42: ='Analisa RAP IV'!O179 -> 6 | R42: ='Analisa RAP IV'!O181 -> 1 | AE42: ='Analisa RAP IV'!O183 -> 1725 | AQ42: ='Analisa RAP IV'!O184 -> 25 | BK42: ='Analisa RAP IV'!U177 -> 20670000 | BL42: ='Analisa RAP IV'!W177 -> 3059403.4 | BM42: ='Analisa RAP IV'!X177 -> 12.892879 | BN42: ='Analisa RAP IV'!Z177 -> 1200 | BO42: =E42*BN42 -> 1971348 | BP42: ='Analisa RAP IV'!AC177 -> 20521348 | BQ42: ='Analisa RAP IV'!AD177 -> 3208055.4 | BR42: ='Analisa RAP IV'!AE177 -> 13.519326 | BS42: ='Analisa RAP IV'!AG177 -> 12000 | BT42: =E42*BS42 -> 19713480 | BU42: ='Analisa RAP IV'!AJ177 -> 19713480 | BV42: ='Analisa RAP IV'!AK177 -> 4015923.4 | BW42: ='Analisa RAP IV'!AL177 -> 16.923828
B43: c. Bekisting | E43: 90.29 | F43: M2 | G43: ='Analisa '!K145 -> 165749.5 | H43: =ROUND(E43*G43,2) -> 14965522 | I43: =H43/$H$86*100 -> 1.1022463 | J43: ='Analisa RAP IV'!K265 -> 2 | K43: ='Analisa RAP IV'!O266 -> 24 | N43: ='Analisa RAP IV'!O267 -> 12 | R43: ='Analisa RAP IV'!O269 -> 1 | S43: ='Analisa RAP IV'!O271 -> 2 | AU43: ='Analisa RAP IV'!O273 -> 9 | AY43: ='Analisa RAP IV'!O272 -> 27 | BK43: ='Analisa RAP IV'!U265 -> 12506000 | BL43: ='Analisa RAP IV'!W265 -> 2459522.4 | BM43: ='Analisa RAP IV'!X265 -> 16.434591 | BN43: ='Analisa RAP IV'!Z265 -> 60000 | BO43: =E43*BN43 -> 5417400 | BP43: ='Analisa RAP IV'!AC265 -> 12083400 | BQ43: ='Analisa RAP IV'!AD265 -> 2882122.4 | BR43: ='Analisa RAP IV'!AE265 -> 19.258415 | BS43: ='Analisa RAP IV'!AG265 -> 130000 | BT43: =E43*BS43 -> 11737700 | BU43: ='Analisa RAP IV'!AJ265 -> 11737700 | BV43: ='Analisa RAP IV'!AK265 -> 3227822.4 | BW43: ='Analisa RAP IV'!AL265 -> 21.568391
...

Sheet Analisa RAP I
B1: ANALISA RENCANA ANGGARAN PROYEK (RAP)
B3: =+Rekapitulasi!A4 -> PEKERJAAN | D3: : | E3: =RAP!B18 -> PEKERJAAN PERSIAPAN
B5: Catatan :
C6: diinput dengan di link kan ke Bobot Nilai / Analisa Upah / Harga Bahan / Harga Material
C7: diinput manual (diisi manual)
B9: I.1. | C9: =RAP!B19 -> Pengukuran dan Pemasangan Bouwplank
B10: NO. | C10: SNI | D10: KODE | E10: KOEF. | F10: SAT. | G10: URAIAN PEKERJAAN | J10: RAP DENGAN BAYARAN (UPAH TENAGA HARIAN) | Y10: RAP DENGAN BAYARAN (UPAH TENAGA BORONGAN) | AF10: RAP DENGAN BAYARAN (UPAH TENAGA + MATERIAL BORONGAN)
J11: VOLUME | K11: DURASI | L11: JUMLAH RESOURCE | Q11: HARGA UPAH / MATERIAL / ALAT RAP | R11: BIAYA RESOURCE | U11: TOTAL BIAYA RAP | V11: TOTAL BIAYA RAB | W11: PROFIT DAN OVERHEAD | X11: % PROFIT DAN OVERHEAD | Y11: Harga Borong Jasa (Tenaga) | AA11: Total Harga Biaya Upah | AB11: Total Biaya Material + Peralatan | AC11: TOTAL BIAYA RAP | AD11: PROFIT DAN OVERHEAD | AE11: % PROFIT DAN OVERHEAD | AF11: Harga Borong Jasa (Tenaga + Material) | AH11: Total Harga Biaya Upah + Material | AI11: Total Biaya Peralatan | AJ11: TOTAL BIAYA RAP | AK11: PROFIT DAN OVERHEAD | AL11: % PROFIT DAN OVERHEAD
K12: (Hari) | L12: Jumlah Tenaga | M12: Jumlah Bahan | N12: Jumlah Alat | O12: Penyesuaian | P12: Satuan | Q12: (Rp) | R12: Biaya Tenaga | S12: Biaya Bahan | T12: Biaya Alat | U12: (Rp.) | V12: (Rp.) | W12: (Rp.) | X12: (%) | Y12: Harga (Rp) | Z12: Penyesuaian (Rp) | AA12: (Rp) | AB12: (Rp) | AC12: (Rp) | AD12: (Rp) | AE12: (Rp) | AF12: Harga (Rp) | AG12: Penyesuaian (Rp) | AH12: (Rp) | AI12: (Rp) | AJ12: (Rp) | AK12: (Rp) | AL12: (Rp)
B13: A | C13: B | D13: C | E13: D | F13: E | G13: F | J13: I | K13: J | L13: K = (D x I) / J | M13: L= D x I | N13: M = D x I | O13: N = Penyesuaian K, L, dan M | P13: O | Q13: P | R13: Q = J x N X P | S13: R = N x P | T13: S = N x P | U13: T = Total Q+R+S | V13: U | W13: V = U - T | X13: W = V/Ux 100 | Y13: X = Total Q / I | Z13: Y = Penyesuaian X | AA13: Z = Y x I | AB13: AA = Total R + Total S | AC13: AB = Z + AA | AD13: AC = U - AB | AE13: AD = AC/U X 100 | AF13: AE = (Total Q + Total R) / I | AG13: AF = Penyesuaian AE | AH13: AG = AF x I | AI13: AH = Total S | AJ13: AI = AG + AH | AK13: AJ = U - AI | AL13: AK = AJ/U X 100
B14: 1 | C14: A.2.2.1.4 | E14: 1 | F14: M' | G14: Pengukuran dan Pemasangan Bouwplank
F15: A | G15: TENAGA | J15: =RAP!E19 -> 126.61 | K15: 2 | U15: =SUM(R16:R24)+(SUM(S16:S24)+SUM(T16:T24)) -> 11470000 | V15: =RAP!H19 -> 12812932 | W15: =V15-U15 -> 1342932 | X15: =W15/V15*100 -> 10.481067 | Y15: =SUM(R16:R24)/J15 -> 16744.333 | Z15: 16000 | AA15: =J15*Z15 -> 2025760 | AB15: =SUM(S15:S24)+SUM(T15:T24) -> 9350000 | AC15: =AA15+AB15 -> 11375760 | AD15: =V15-AC15 -> 1437172 | AE15: =AD15/V15*100 -> 11.216574 | AF15: =(SUM(R15:R24)+SUM(S15:S24))/J15 -> 90593.16 | AG15: 90000 | AH15: =AG15*J15 -> 11394900 | AI15: =SUM(T15:T24) -> 0 | AJ15: =AH15+AI15 -> 11394900 | AK15: =V15-AJ15 -> 1418032 | AL15: =AK15/V15*100 -> 11.067194
D16: L.01 | E16: 0.1 | F16: OH | G16: Pekerja | L16: =E16*J15/K15 -> 6.3305 | O16: 6 | P16: =F16 -> OH | Q16: ='Analisa Upah RAP'!G5 -> 75000 | R16: =O16*Q16*K15 -> 900000
D17: L.02 | E17: 0.1 | F17: OH | G17: Tukang Kayu | L17: =E17*J15/K15 -> 6.3305 | O17: 6 | P17: =F17 -> OH | Q17: ='Analisa Upah RAP'!G6 -> 85000 | R17: =O17*Q17*K15 -> 1020000
D18: L.03 | E18: 0.01 | F18: OH | G18: Kepala Tukang | L18: =E18*J15/K15 -> 0.63305 | O18: 0 | P18: =F18 -> OH | Q18: ='Analisa Upah RAP'!G11 -> 90000 | R18: =O18*Q18*K15 -> 0
D19: L.04 | E19: 0.005 | F19: OH | G19: Mandor | L19: =E19*J15/K15 -> 0.316525 | O19: 1 | P19: =F19 -> OH | Q19: ='Analisa Upah RAP'!G12 -> 100000 | R19: =O19*Q19*K15 -> 200000
F20: B | G20: BAHAN
E21: 0.012 | F21: M3 | G21: Kayu Balok 5/7 | M21: =E21*J15 -> 1.51932 | O21: 1.5 | P21: =F21 -> M3 | Q21: ='Harga Bahan RAP'!G28 -> 3000000 | S21: =O21*Q21 -> 4500000
E22: 0.02 | F22: Kg | G22: Paku 2"- 3" | L22: =Q22/O22 -> 8000 | M22: =E22*J15 -> 2.5322 | O22: 2.5 | P22: =F22 -> Kg | Q22: ='Harga Bahan RAP'!G122 -> 20000 | S22: =O22*Q22 -> 50000
E23: 0.007 | F23: M3 | G23: Kayu Papan 3/20 | M23: =E23*J15 -> 0.88627 | O23: 1 | P23: =F23 -> M3 | Q23: ='Harga Bahan RAP'!G27 -> 4800000 | S23: =O23*Q23 -> 4800000
F24: C | G24: PERALATAN | O24: 0 | P24: 0 | Q24: 0 | T24: =O24*Q24 -> 0
F25: D | G25: Jumlah A + B + C
F26: E | G26: Overhead & Profit | I26: 0.15
F27: F | G27: Harga Satuan Pekerjaan ( D + E )
B29: I.2 | C29: =RAP!B20 -> Pembersihan Lapangan dan Perataan
B30: NO. | C30: SNI | D30: KODE | E30: KOEF. | F30: SAT. | G30: URAIAN PEKERJAAN | J30: RAP DENGAN BAYARAN (UPAH TENAGA HARIAN) | Y30: RAP DENGAN BAYARAN (UPAH TENAGA BORONGAN) | AF30: RAP DENGAN BAYARAN (UPAH TENAGA + MATERIAL BORONGAN)
J31: VOLUME | K31: DURASI | L31: JUMLAH RESOURCE | Q31: HARGA UPAH / MATERIAL / ALAT RAP | R31: BIAYA RESOURCE | U31: TOTAL BIAYA RAP | V31: TOTAL BIAYA RAB | W31: PROFIT DAN OVERHEAD | X31: % PROFIT DAN OVERHEAD | Y31: Harga Borong Jasa (Tenaga) | AA31: Total Harga Biaya Upah | AB31: Total Biaya Material + Peralatan | AC31: TOTAL BIAYA RAP | AD31: PROFIT DAN OVERHEAD | AE31: % PROFIT DAN OVERHEAD | AF31: Harga Borong Jasa (Tenaga + Material) | AH31: Total Harga Biaya Upah + Material | AI31: Total Biaya Peralatan | AJ31: TOTAL BIAYA RAP | AK31: PROFIT DAN OVERHEAD | AL31: % PROFIT DAN OVERHEAD
K32: (Hari) | L32: Jumlah Tenaga | M32: Jumlah Bahan | N32: Jumlah Alat | O32: Penyesuaian | P32: Satuan | Q32: (Rp) | R32: Biaya Tenaga | S32: Biaya Bahan | T32: Biaya Alat | U32: (Rp.) | V32: (Rp.) | W32: (Rp.) | X32: (%) | Y32: Harga (Rp) | Z32: Penyesuaian (Rp) | AA32: (Rp) | AB32: (Rp) | AC32: (Rp) | AD32: (Rp) | AE32: (Rp) | AF32: Harga (Rp) | AG32: Penyesuaian (Rp) | AH32: (Rp) | AI32: (Rp) | AJ32: (Rp) | AK32: (Rp) | AL32: (Rp)
B33: A | C33: B | D33: C | E33: D | F33: E | G33: F | J33: I | K33: J | L33: K = (D x I) / J | M33: L= D x I | N33: M = D x I | O33: N = Penyesuaian K, L, dan M | P33: O | Q33: P | R33: Q = J x N X P | S33: R = N x P | T33: S = N x P | U33: T = Total Q+R+S | V33: U | W33: V = U - T | X33: W = V/Ux 100 | Y33: X = Total Q / I | Z33: Y = Penyesuaian X | AA33: Z = Y x I | AB33: AA = Total R + Total S | AC33: AB = Z + AA | AD33: AC = U - AB | AE33: AD = AC/U X 100 | AF33: AE = (Total Q + Total R) / I | AG33: AF = Penyesuaian AE | AH33: AG = AF x I | AI33: AH = Total S | AJ33: AI = AG + AH | AK33: AJ = U - AI | AL33: AK = AJ/U X 100
B34: 2 | C34: A.2.2.1.9 | E34: 1 | F34: M2 | G34: Membersihkan Lapangan dan Perataan
F35: A | G35: TENAGA | J35: =RAP!E20 -> 180 | K35: 3 | U35: =SUM(R36:R43)+(SUM(S36:S43)+SUM(T36:T43)) -> 1650000 | V35: =RAP!H20 -> 2691000 | W35: =V35-U35 -> 1041000 | X35: =W35/V35*100 -> 38.684504 | Y35: =SUM(R36:R43)/J35 -> 9166.6667 | Z35: 9000 | AA35: =J35*Z35 -> 1620000 | AB35: =SUM(S35:S43)+SUM(T35:T43) -> 0 | AC35: =AA35+AB35 -> 1620000 | AD35: =V35-AC35 -> 1071000 | AE35: =AD35/V35*100 -> 39.799331 | AF35: =(SUM(R35:R43)+SUM(S35:S43))/J35 -> 9166.6667 | AG35: 9000 | AH35: =AG35*J35 -> 1620000 | AI35: =SUM(T35:T43) -> 0 | AJ35: =AH35+AI35 -> 1620000 | AK35: =V35-AJ35 -> 1071000 | AL35: =AK35/V35*100 -> 39.799331
D36: L.01 | E36: 0.1 | F36: OH | G36: Pekerja | L36: =E36*J35/K35 -> 6 | O36: 6 | P36: =F36 -> OH | Q36: ='Analisa Upah RAP'!G5 -> 75000 | R36: =O36*Q36*K35 -> 1350000
D37: L.04 | E37: 0.05 | F37: OH | G37: Mandor | L37: =E37*J35/K35 -> 3 | O37: 1 | P37: =F37 -> OH | Q37: ='Analisa Upah RAP'!G12 -> 100000 | R37: =O37*Q37*K35 -> 300000
F38: B | G38: BAHAN
E39: 0 | F39: - | G39: - | M39: =E39*J35 -> 0 | O39: 0 | P39: =E39 -> 0 | Q39: 0 | S39: =O39*Q39 -> 0
E40: 0 | F40: - | G40: - | M40: =E40*J35 -> 0 | O40: 0 | P40: =E40 -> 0 | Q40: 0 | S40: =O40*Q40 -> 0
E41: 0 | F41: - | G41: - | M41: =E41*J35 -> 0 | O41: 0 | P41: =E41 -> 0 | Q41: 0 | S41: =O41*Q41 -> 0
F42: C | G42: PERALATAN | P42: =E42 -> 0 | Q42: 0
E43: 0 | F43: - | G43: - | N43: =E43*J35 -> 0 | O43: 0 | P43: =E43 -> 0 | Q43: 0 | T43: =O43*Q43 -> 0
F44: D | G44: Jumlah A + B + C
...

Sheet Analisa RAP II
B1: ANALISA RENCANA ANGGARAN PROYEK (RAP)
B3: =+Rekapitulasi!A4 -> PEKERJAAN | D3: : | E3: =RAP!B23 -> PEKERJAAN TANAH
B5: Catatan :
C6: diinput dengan di link kan ke Bobot Nilai / Analisa Upah / Harga Bahan / Harga Material
C7: diinput manual (diisi manual)
B9: II.1 | C9: =RAP!B24 -> Galian Tanah Biasa 1 m
B10: NO. | C10: SNI | D10: KODE | E10: KOEF. | F10: SAT. | G10: URAIAN PEKERJAAN | J10: RAP DENGAN BAYARAN (UPAH TENAGA HARIAN) | Y10: RAP DENGAN BAYARAN (UPAH TENAGA BORONGAN) | AF10: RAP DENGAN BAYARAN (UPAH TENAGA + MATERIAL BORONGAN)
J11: VOLUME | K11: DURASI | L11: JUMLAH RESOURCE | Q11: HARGA UPAH / MATERIAL / ALAT RAP | R11: BIAYA RESOURCE | U11: TOTAL BIAYA RAP | V11: TOTAL BIAYA RAB | W11: PROFIT DAN OVERHEAD | X11: % PROFIT DAN OVERHEAD | Y11: Harga Borong Jasa (Tenaga) | AA11: Total Harga Biaya Upah | AB11: Total Biaya Material + Peralatan | AC11: TOTAL BIAYA RAP | AD11: PROFIT DAN OVERHEAD | AE11: % PROFIT DAN OVERHEAD | AF11: Harga Borong Jasa (Tenaga + Material) | AH11: Total Harga Biaya Upah + Material | AI11: Total Biaya Peralatan | AJ11: TOTAL BIAYA RAP | AK11: PROFIT DAN OVERHEAD | AL11: % PROFIT DAN OVERHEAD
K12: (Hari) | L12: Jumlah Tenaga | M12: Jumlah Bahan | N12: Jumlah Alat | O12: Penyesuaian | P12: Satuan | Q12: (Rp) | R12: Biaya Tenaga | S12: Biaya Bahan | T12: Biaya Alat | U12: (Rp.) | V12: (Rp.) | W12: (Rp.) | X12: (%) | Y12: Harga (Rp) | Z12: Penyesuaian (Rp) | AA12: (Rp) | AB12: (Rp) | AC12: (Rp) | AD12: (Rp) | AE12: (Rp) | AF12: Harga (Rp) | AG12: Penyesuaian (Rp) | AH12: (Rp) | AI12: (Rp) | AJ12: (Rp) | AK12: (Rp) | AL12: (Rp)
B13: A | C13: B | D13: C | E13: D | F13: E | G13: F | J13: I | K13: J | L13: K = (D x I) / J | M13: L= D x I | N13: M = D x I | O13: N = Penyesuaian K, L, dan M | P13: O | Q13: P | R13: Q = J x N X P | S13: R = N x P | T13: S = N x P | U13: T = Total Q+R+S | V13: U | W13: V = U - T | X13: W = V/Ux 100 | Y13: X = Total Q / I | Z13: Y = Penyesuaian X | AA13: Z = Y x I | AB13: AA = Total R + Total S | AC13: AB = Z + AA | AD13: AC = U - AB | AE13: AD = AC/U X 100 | AF13: AE = (Total Q + Total R) / I | AG13: AF = Penyesuaian AE | AH13: AG = AF x I | AI13: AH = Total S | AJ13: AI = AG + AH | AK13: AJ = U - AI | AL13: AK = AJ/U X 100
B14: 1 | C14: A.2.3.1.1 | E14: 1 | F14: M3 | G14: Menggali Tanah Biasa sedalam 1 M
F15: A | G15: TENAGA | J15: =RAP!E24 -> 40 | K15: 3 | U15: =SUM(R16:R23)+(SUM(S16:S23)+SUM(T16:T23)) -> 2550000 | V15: =RAP!H24 -> 2714000 | W15: =V15-U15 -> 164000 | X15: =W15/V15*100 -> 6.0427413 | Y15: =SUM(R16:R23)/J15 -> 63750 | Z15: 60000 | AA15: =J15*Z15 -> 2400000 | AB15: =SUM(S15:S23)+SUM(T15:T23) -> 0 | AC15: =AA15+AB15 -> 2400000 | AD15: =V15-AC15 -> 314000 | AE15: =AD15/V15*100 -> 11.569639 | AF15: =(SUM(R15:R23)+SUM(S15:S23))/J15 -> 63750 | AG15: 60000 | AH15: =AG15*J15 -> 2400000 | AI15: =SUM(T15:T23) -> 0 | AJ15: =AH15+AI15 -> 2400000 | AK15: =V15-AJ15 -> 314000 | AL15: =AK15/V15*100 -> 11.569639
D16: L.01 | E16: 0.75 | F16: OH | G16: Pekerja | L16: =E16*J15/K15 -> 10 | O16: 10 | P16: =F16 -> OH | Q16: ='Analisa Upah RAP'!G5 -> 75000 | R16: =O16*Q16*K15 -> 2250000
D17: L.04 | E17: 0.025 | F17: OH | G17: Mandor | L17: =E17*J15/K15 -> 0.33333333 | O17: 1 | P17: =F17 -> OH | Q17: ='Analisa Upah RAP'!G12 -> 100000 | R17: =O17*Q17*K15 -> 300000
F18: B | G18: BAHAN
E19: 0 | F19: - | G19: - | M19: =E19*J15 -> 0 | O19: 0 | P19: =E19 -> 0 | Q19: 0 | S19: =O19*Q19 -> 0
E20: 0 | F20: - | G20: - | M20: =E20*J15 -> 0 | O20: 0 | P20: =E20 -> 0 | Q20: 0 | S20: =O20*Q20 -> 0
E21: 0 | F21: - | G21: - | M21: =E21*J15 -> 0 | O21: 0 | P21: =E21 -> 0 | Q21: 0 | S21: =O21*Q21 -> 0
F22: C | G22: PERALATAN | P22: =E22 -> 0 | Q22: 0
E23: 0 | F23: - | G23: - | N23: =E23*J15 -> 0 | O23: 0 | P23: =E23 -> 0 | Q23: 0 | T23: =O23*Q23 -> 0
F24: D | G24: Jumlah A + B + C
F25: E | G25: Overhead & Profit | I25: 0.15
F26: F | G26: Harga Satuan Pekerjaan ( D + E )
B28: II.2 | C28: =RAP!B25 -> Galian Tanah Biasa 2 m
B29: NO. | C29: SNI | D29: KODE | E29: KOEF. | F29: SAT. | G29: URAIAN PEKERJAAN | J29: RAP DENGAN BAYARAN (UPAH TENAGA HARIAN) | Y29: RAP DENGAN BAYARAN (UPAH TENAGA BORONGAN) | AF29: RAP DENGAN BAYARAN (UPAH TENAGA + MATERIAL BORONGAN)
J30: VOLUME | K30: DURASI | L30: JUMLAH RESOURCE | Q30: HARGA UPAH / MATERIAL / ALAT RAP | R30: BIAYA RESOURCE | U30: TOTAL BIAYA RAP | V30: TOTAL BIAYA RAB | W30: PROFIT DAN OVERHEAD | X30: % PROFIT DAN OVERHEAD | Y30: Harga Borong Jasa (Tenaga) | AA30: Total Harga Biaya Upah | AB30: Total Biaya Material + Peralatan | AC30: TOTAL BIAYA RAP | AD30: PROFIT DAN OVERHEAD | AE30: % PROFIT DAN OVERHEAD | AF30: Harga Borong Jasa (Tenaga + Material) | AH30: Total Harga Biaya Upah + Material | AI30: Total Biaya Peralatan | AJ30: TOTAL BIAYA RAP | AK30: PROFIT DAN OVERHEAD | AL30: % PROFIT DAN OVERHEAD
K31: (Hari) | L31: Jumlah Tenaga | M31: Jumlah Bahan | N31: Jumlah Alat | O31: Penyesuaian | P31: Satuan | Q31: (Rp) | R31: Biaya Tenaga | S31: Biaya Bahan | T31: Biaya Alat | U31: (Rp.) | V31: (Rp.) | W31: (Rp.) | X31: (%) | Y31: Harga (Rp) | Z31: Penyesuaian (Rp) | AA31: (Rp) | AB31: (Rp) | AC31: (Rp) | AD31: (Rp) | AE31: (Rp) | AF31: Harga (Rp) | AG31: Penyesuaian (Rp) | AH31: (Rp) | AI31: (Rp) | AJ31: (Rp) | AK31: (Rp) | AL31: (Rp)
B32: A | C32: B | D32: C | E32: D | F32: E | G32: F | J32: I | K32: J | L32: K = (D x I) / J | M32: L= D x I | N32: M = D x I | O32: N = Penyesuaian K, L, dan M | P32: O | Q32: P | R32: Q = J x N X P | S32: R = N x P | T32: S = N x P | U32: T = Total Q+R+S | V32: U | W32: V = U - T | X32: W = V/Ux 100 | Y32: X = Total Q / I | Z32: Y = Penyesuaian X | AA32: Z = Y x I | AB32: AA = Total R + Total S | AC32: AB = Z + AA | AD32: AC = U - AB | AE32: AD = AC/U X 100 | AF32: AE = (Total Q + Total R) / I | AG32: AF = Penyesuaian AE | AH32: AG = AF x I | AI32: AH = Total S | AJ32: AI = AG + AH | AK32: AJ = U - AI | AL32: AK = AJ/U X 100
B33: 2 | C33: A.2.3.1.2 | E33: 1 | F33: M3 | G33: Menggali Tanah Biasa sedalam 2 M
F34: A | G34: TENAGA | J34: =RAP!E25 -> 28 | K34: 4 | U34: =SUM(R35:R41)+(SUM(S35:S41)+SUM(T35:T41)) -> 2200000 | V34: =RAP!H25 -> 2332890 | W34: =V34-U34 -> 132890 | X34: =W34/V34*100 -> 5.696368 | Y34: =SUM(R35:R41)/J34 -> 78571.429 | Z34: 60000 | AA34: =J34*Z34 -> 1680000 | AB34: =SUM(S34:S41)+SUM(T34:T41) -> 0 | AC34: =AA34+AB34 -> 1680000 | AD34: =V34-AC34 -> 652890 | AE34: =AD34/V34*100 -> 27.986317 | AF34: =(SUM(R34:R41)+SUM(S34:S41))/J34 -> 78571.429 | AG34: 60000 | AH34: =AG34*J34 -> 1680000 | AI34: =SUM(T34:T41) -> 0 | AJ34: =AH34+AI34 -> 1680000 | AK34: =V34-AJ34 -> 652890 | AL34: =AK34/V34*100 -> 27.986317
D35: L.01 | E35: 0.9 | F35: OH | G35: Pekerja | L35: =E35*J34/K34 -> 6.3 | O35: 6 | P35: =F35 -> OH | Q35: ='Analisa Upah RAP'!G5 -> 75000 | R35: =O35*Q35*K34 -> 1800000
D36: L.04 | E36: 0.045 | F36: OH | G36: Mandor | L36: =E36*J34/K34 -> 0.315 | O36: 1 | P36: =F36 -> OH | Q36: ='Analisa Upah RAP'!G12 -> 100000 | R36: =O36*Q36*K34 -> 400000
F37: B | G37: BAHAN | M37: =E37*J34 -> 0 | O37: 0 | P37: =E37 -> 0 | Q37: 0 | S37: =O37*Q37 -> 0
E38: 0 | F38: - | G38: - | M38: =E38*J34 -> 0 | O38: 0 | P38: =E38 -> 0 | Q38: 0 | S38: =O38*Q38 -> 0
E39: 0 | F39: - | G39: - | M39: =E39*J34 -> 0 | O39: 0 | P39: =E39 -> 0 | Q39: 0 | S39: =O39*Q39 -> 0
E40: 0 | F40: - | G40: - | M40: =E40*J34 -> 0 | O40: 0 | P40: =E40 -> 0 | Q40: 0 | S40: =O40*Q40 -> 0
F41: C | G41: PERALATAN | P41: =E41 -> 0 | Q41: 0
E42: 0 | F42: - | G42: - | N42: =E42*J34 -> 0 | O42: 0 | P42: =E42 -> 0 | Q42: 0 | T42: =O42*Q42 -> 0
F43: D | G43: Jumlah A + B + C
F44: E | G44: Overhead & Profit | I44: 0.15
...

Sheet Analisa RAP III
B1: ANALISA RENCANA ANGGARAN PROYEK (RAP)
B3: =+Rekapitulasi!A4 -> PEKERJAAN | D3: : | E3: =RAP!B30 -> PEKERJAAN PONDASI
B5: Catatan :
C6: diinput dengan di link kan ke Bobot Nilai / Analisa Upah / Harga Bahan / Harga Material
C7: diinput manual (diisi manual)
C8: diubah satuannya
B10: III.1 | C10: =RAP!B31 -> Pasangan Batu Belah 1Pc : 4Ps
B11: NO. | C11: SNI | D11: KODE | E11: KOEF. | F11: SAT. | G11: URAIAN PEKERJAAN | J11: RAP DENGAN BAYARAN (UPAH TENAGA HARIAN) | Y11: RAP DENGAN BAYARAN (UPAH TENAGA BORONGAN) | AF11: RAP DENGAN BAYARAN (UPAH TENAGA + MATERIAL BORONGAN)
J12: VOLUME | K12: DURASI | L12: JUMLAH RESOURCE | Q12: HARGA UPAH / MATERIAL / ALAT RAP | R12: BIAYA RESOURCE | U12: TOTAL BIAYA RAP | V12: TOTAL BIAYA RAB | W12: PROFIT DAN OVERHEAD | X12: % PROFIT DAN OVERHEAD | Y12: Harga Borong Jasa (Tenaga) | AA12: Total Harga Biaya Upah | AB12: Total Biaya Material + Peralatan | AC12: TOTAL BIAYA RAP | AD12: PROFIT DAN OVERHEAD | AE12: % PROFIT DAN OVERHEAD | AF12: Harga Borong Jasa (Tenaga + Material) | AH12: Total Harga Biaya Upah + Material | AI12: Total Biaya Peralatan | AJ12: TOTAL BIAYA RAP | AK12: PROFIT DAN OVERHEAD | AL12: % PROFIT DAN OVERHEAD
K13: (Hari) | L13: Jumlah Tenaga | M13: Jumlah Bahan | N13: Jumlah Alat | O13: Penyesuaian | P13: Satuan | Q13: (Rp) | R13: Biaya Tenaga | S13: Biaya Bahan | T13: Biaya Alat | U13: (Rp.) | V13: (Rp.) | W13: (Rp.) | X13: (%) | Y13: Harga (Rp) | Z13: Penyesuaian (Rp) | AA13: (Rp) | AB13: (Rp) | AC13: (Rp) | AD13: (Rp) | AE13: (Rp) | AF13: Harga (Rp) | AG13: Penyesuaian (Rp) | AH13: (Rp) | AI13: (Rp) | AJ13: (Rp) | AK13: (Rp) | AL13: (Rp)
B14: A | C14: B | D14: C | E14: D | F14: E | G14: F | J14: I | K14: J | L14: K = (D x I) / J | M14: L= D x I | N14: M = D x I | O14: N = Penyesuaian K, L, dan M | P14: O | Q14: P | R14: Q = J x N X P | S14: R = N x P | T14: S = N x P | U14: T = Total Q+R+S | V14: U | W14: V = U - T | X14: W = V/Ux 100 | Y14: X = Total Q / I | Z14: Y = Penyesuaian X | AA14: Z = Y x I | AB14: AA = Total R + Total S | AC14: AB = Z + AA | AD14: AC = U - AB | AE14: AD = AC/U X 100 | AF14: AE = (Total Q + Total R) / I | AG14: AF = Penyesuaian AE | AH14: AG = AF x I | AI14: AH = Total S | AJ14: AI = AG + AH | AK14: AJ = U - AI | AL14: AK = AJ/U X 100
B15: 9 | C15: A.3.2.1.2 | E15: 1 | F15: M3 | G15: Pemasangan Pondasi Batu Belah 1SP : 4 PP
F16: A | G16: Tenaga | J16: =RAP!E31 -> 48.9 | K16: 4 | U16: =SUM(R16:R29)+(SUM(S16:S29)+SUM(T16:T29)) -> 43847500 | V16: =RAP!H31 -> 51047321 | W16: =V16-U16 -> 7199821.2 | X16: =W16/V16*100 -> 14.10421 | Y16: =SUM(R16:R29)/J16 -> 181186.09 | Z16: 180000 | AA16: =J16*Z16 -> 8802000 | AB16: =SUM(S16:S29)+SUM(T16:T29) -> 34987500 | AC16: =AA16+AB16 -> 43789500 | AD16: =V16-AC16 -> 7257821.2 | AE16: =AD16/V16*100 -> 14.21783 | AF16: =(SUM(R16:R29)+SUM(S16:S29))/J16 -> 896676.89 | AG16: 875000 | AH16: =AG16*J16 -> 42787500 | AI16: =SUM(T16:T29) -> 0 | AJ16: =AH16+AI16 -> 42787500 | AK16: =V16-AJ16 -> 8259821.2 | AL16: =AK16/V16*100 -> 16.180714
D17: L.01 | E17: 1.5 | F17: OH | G17: Pekerja | L17: =E17*J16/K16 -> 18.3375 | O17: 18 | P17: =F17 -> OH | Q17: ='Analisa Upah RAP'!G5 -> 75000 | R17: =O17*Q17*K16 -> 5400000
D18: L.02 | E18: 0.75 | F18: OH | G18: Tukang Batu | L18: =E18*J16/K16 -> 9.16875 | O18: 9 | P18: =F18 -> OH | Q18: ='Analisa Upah RAP'!G7 -> 85000 | R18: =O18*Q18*K16 -> 3060000
D19: L.03 | E19: 0.075 | F19: OH | G19: Kepala Tukang | L19: =E19*J16/K16 -> 0.916875 | O19: 0 | P19: =F19 -> OH | Q19: ='Analisa Upah RAP'!G11 -> 90000 | R19: =O19*Q19*K16 -> 0
D20: L.04 | E20: 0.075 | F20: OH | G20: Mandor | L20: =E20*J16/K16 -> 0.916875 | O20: 1 | P20: =F20 -> OH | Q20: ='Analisa Upah RAP'!G12 -> 100000 | R20: =O20*Q20*K16 -> 400000
F21: B | G21: Bahan
E22: 1.2 | F22: m3 | G22: Batu Belah | M22: =E22*J16 -> 58.68 | O22: 59 | P22: =F22 -> m3 | Q22: ='Harga Bahan RAP'!G6 -> 300000 | S22: =O22*Q22 -> 17700000
E23: =163/40 -> 4.075 | F23: Zak | G23: Portland Sement | M23: =E23*J16 -> 199.2675 | O23: 200 | P23: =F23 -> Zak | Q23: ='Harga Bahan RAP'!G11 -> 45000 | S23: =O23*Q23 -> 9000000
E24: 0.52 | F24: m3 | G24: Pasir Pasang | M24: =E24*J16 -> 25.428 | O24: 25.5 | P24: =F24 -> m3 | Q24: ='Harga Bahan RAP'!G9 -> 325000 | S24: =O24*Q24 -> 8287500
F25: C | G25: PERALATAN
E26: 0 | F26: - | G26: - | N26: =E26*J16 -> 0 | P26: =F26 -> - | T26: =O26*Q26 -> 0
F27: D | G27: Jumlah A + B + C
F28: E | G28: Overhead & Profit | I28: 0.15
F29: F | G29: Harga Satuan Pekerjaan (D+E)

Sheet Analisa RAP IV
B1: ANALISA RENCANA ANGGARAN PROYEK (RAP)
B3: =+Rekapitulasi!A4 -> PEKERJAAN | D3: : | E3: =RAP!B33 -> PEKERJAAN BETON
B5: Catatan :
C6: diinput dengan di link kan ke Bobot Nilai / Analisa Upah / Harga Bahan / Harga Material
C7: diinput manual (diisi manual)
C8: diubah satuannya
C9: Penambahan Alat disesuaikan dengan kebutuhan
B11: IV.1 | C11: =RAP!B34 -> Lantai Kerja (Rabat Beton) dibawah Foot Plat T=10 cm
B12: NO. | C12: SNI | D12: KODE | E12: KOEF. | F12: SAT. | G12: URAIAN PEKERJAAN | J12: RAP DENGAN BAYARAN (UPAH TENAGA HARIAN) | Y12: RAP DENGAN BAYARAN (UPAH TENAGA BORONGAN) | AF12: RAP DENGAN BAYARAN (UPAH TENAGA + MATERIAL BORONGAN)
